Workbook
Name beta: '[1]DCF Valuation'!$C$20
Name beta: 'DCF Valuation'!$C$20
Name company: [1]Cover!$C$2
Name company: Cover!$C$2
Name costofdebt: '[1]DCF Valuation'!$C$22
Name costofdebt: 'DCF Valuation'!$C$22
Name currentprice: [1]Cover!$C$4
Name currentprice: Cover!$C$4
Name dilutedshares: 'Comparables '!$C$7
Name dilutedshares: #REF!
Name equityvalue: 'Comparables '!$C$8
Name equityvalue: #REF!
Name ev: 'Comparables '!$C$10
Name ev: #REF!
Name mrp: '[1]DCF Valuation'!$C$19
Name mrp: 'DCF Valuation'!$C$19
Name name: [1]Cover!$C$2
Name netdebt: 'Comparables '!$C$9
Name netdebt: #REF!
Name rd: '[1]DCF Valuation'!$C$24
Name rd: 'DCF Valuation'!$C$24
Name re: '[1]DCF Valuation'!$C$21
Name re: 'DCF Valuation'!$C$21
Name rf: '[1]DCF Valuation'!$C$18
Name rf: 'DCF Valuation'!$C$18
Name rm: '[1]DCF Valuation'!$C$17
Name rm: 'DCF Valuation'!$C$17
Name taxrate: '[1]DCF Valuation'!$C$23
Name taxrate: 'DCF Valuation'!$C$23
Name tgr: '[1]DCF Valuation'!$D$47
Name tgr: 'DCF Valuation'!$D$46
Name wacc: '[1]DCF Valuation'!$C$25
Name wacc: 'DCF Valuation'!$C$25

Sheet Cover
B2: Company | C2: Nike
B3: Ticker | C3: NYSE: NKE
B4: Price | C4: 60
B5: Team Number | C5: Team Apex
B7: =company&" – Financial Model" -> Nike – Financial Model
B15: Sauder Capital Markets Challenge
C16: First Round Case
B17: =TODAY() -> 46022
B19: Case Sponsor
B27: Gold Sponsor
B29: Board of Directors

Sheet Instructions
B1: Sauder Capital Markets Challenge
B2: =company -> Nike
B3: Financial Model
B4: Instructions
B6: General Instructions
B8: 1 | C8: Follow the color and formatting guide below
B9: =B8+1 -> 2 | C9: Keep all financial statements on an annual basis
B10: =B9+1 -> 3 | C10: All figures should be in $USDm unless otherwise specified
B11: =B10+1 -> 4 | C11: Do not overwrite formulas on the existing model. Add new lines only.
B12: =B11+1 -> 5 | C12: Keep all schedules in the "Supporting Schedules" tab
B13: =B12+1 -> 6 | C13: Do not delete or add any tabs
B14: =B13+1 -> 7 | C14: Teams are permitted to use Generative AI to learn concepts; other uses must be disclosed in the pitch deck as references
B17: DCF Valuation Instructions
B19: 1 | C19: Pull the company's historical financials from its filings or a data provider
B20: =B19+1 -> 2 | C20: Map the figures into the Financial Statements tab and use the same name lines as the template
B21: =B20+1 -> 3 | C21: Add or remove detail by inserting new rows while keeping the final subtotals aligned
B22: =B21+1 -> 4 | C22: Ensure all new rows link correctly to the relevant totals
B23: =B22+1 -> 5 | C23: If historical numbers require reclassification, adjust them so that revenue, COGS, operating costs, depreciation, taxes, working capital, capital spending, and interest items align with the structure given
B24: =B23+1 -> 6 | C24: Forecast revenue, margins, operating costs, depreciation, interest, taxes, and any other required items
B25: =B24+1 -> 7 | C25: Keep formulas in black for any pattern that repeats across multiple periods
B26: =B25+1 -> 8 | C26: Create supporting schedules to drive items in the cash flow statement and tie them into the balance sheet; suggested schedules are in the Supporting Schedules tab
B27: =B26+1 -> 9 | C27: Go to the DCF valuation tab and link free cash flow from the statements
B28: =B27+1 -> 10 | C28: Compute the present value of each free cash flow year in black
B29: =B28+1 -> 11 | C29: Enter WACC inputs, terminal growth, and other assumptions in blue in the yellow input box
B30: =B29+1 -> 12 | C30: Confirm that the model produces a final implied share price and implied upside
B31: =B30+1 -> 13 | C31: Optional: add charts, summary tables, and additional outputs for presentation use
B34: Comparable & Precedent Transaction Valuation Instructions
B36: 1 | C36: Select comparable companies and precedent transactions
B37: =B36+1 -> 2 | C37: Include rationale briefly in far right column for the precedent transactions
B38: =B37+1 -> 3 | C38: Populate cells with comparable companies' relevant data points
B39: =B38+1 -> 4 | C39: Populate cells with precedent transactions relevant deal multiples
B40: =B39+1 -> 5 | C40: Fill out target company's relevant financial data points
B41: =B40+1 -> 6 | C41: Upon all fields being completed, an implied transaction value will populate
B44: Formatting Guides
B46: Color Formatting Guide
B48: Color | C48: Description | D48: Hex Code
B49: Blue | C49: Hardcoded values | D49: #0000FF
B50: Black | C50: Formulas; calculated values | D50: #000000
B51: Green | C51: Reference within sheet | D51: #009B00
B52: Red | C52: Reference to another sheet | D52: #FF0000
...

Sheet Financial Statements
B1: Sauder Capital Markets Challenge
B2: =company -> Nike
B3: Financial Model
B4: Financial Statements
B6: Years | C6: 2020 | D6: =C6+1 -> 2021 | E6: =D6+1 -> 2022 | F6: =E6+1 -> 2023 | G6: =F6+1 -> 2024 | H6: =G6+1 -> 2025 | I6: =H6+1 -> 2026 | J6: =I6+1 -> 2027 | K6: =J6+1 -> 2028 | ... Q6: =P6+1 -> 2034
B8: Income Statement
B10: Revenue | C10: 37403 | D10: 44538 | E10: 46710 | F10: 51217 | G10: 51362 | H10: 46309 | I10: ='Supporting Schedules'!I10 -> 46816.501 | J10: ='Supporting Schedules'!J10 -> 48604.808 | K10: ='Supporting Schedules'!K10 -> 51099.318 | L10: ='Supporting Schedules'!L10 -> 54096.746 | M10: ='Supporting Schedules'!M10 -> 57317.95 | N10: ='Supporting Schedules'!N10 -> 62220.86 | O10: ='Supporting Schedules'!O10 -> 66263.242 | P10: ='Supporting Schedules'!P10 -> 70464.974 | Q10: ='Supporting Schedules'!Q10 -> 74822.066
B11: Revenue Growth % | C11: =IFERROR(C10/B10-1," ") | D11: =IFERROR(D10/C10-1," ") -> 0.1907601 | E11: =IFERROR(E10/D10-1," ") -> 0.048767345 | F11: =IFERROR(F10/E10-1," ") -> 0.096488975 | G11: =IFERROR(G10/F10-1," ") -> 0.0028310912 | H11: =IFERROR(H10/G10-1," ") -> -0.098380125 | I11: =IFERROR(I10/H10-1," ") -> 0.010959005 | J11: =IFERROR(J10/I10-1," ") -> 0.038198226 | ... Q11: =IFERROR(Q10/P10-1," ") -> 0.06183345
B12: Cost of Sales | C12: 21162 | D12: 24576 | E12: 25231 | F12: 28925 | G12: 28475 | H12: 26519 | I12: =I10*'Supporting Schedules'!I51 -> 27072.032 | J12: =J10*'Supporting Schedules'!J51 -> 27863.111 | K12: =K10*'Supporting Schedules'!K51 -> 29037.613 | L12: =L10*'Supporting Schedules'!L51 -> 30470.443 | M12: =M10*'Supporting Schedules'!M51 -> 31998.224 | N12: =N10*'Supporting Schedules'!N51 -> 34735.314 | O12: =O10*'Supporting Schedules'!O51 -> 36992.007 | P12: =P10*'Supporting Schedules'!P51 -> 39337.659 | Q12: =Q10*'Supporting Schedules'!Q51 -> 41770.042
B13: COGS Margin % | C13: =IFERROR(C12/C10," ") -> 0.56578349 | D13: =IFERROR(D12/D10," ") -> 0.55179846 | E13: =IFERROR(E12/E10," ") -> 0.54016271 | F13: =IFERROR(F12/F10," ") -> 0.56475389 | G13: =IFERROR(G12/G10," ") -> 0.55439819 | H13: =IFERROR(H12/H10," ") -> 0.57265326 | I13: =IFERROR(I12/I10," ") -> 0.57825834 | J13: =IFERROR(J12/J10," ") -> 0.57325834 | ... Q13: =IFERROR(Q12/Q10," ") -> 0.55825834
B14: Equals: Gross Profit | C14: =C10-C12 -> 16241 | D14: =D10-D12 -> 19962 | E14: =E10-E12 -> 21479 | F14: =F10-F12 -> 22292 | G14: =G10-G12 -> 22887 | H14: =H10-H12 -> 19790 | I14: =I10-I12 -> 19744.469 | J14: =J10-J12 -> 20741.697 | ... Q14: =Q10-Q12 -> 33052.024
B15: Gross Profit % | C15: =IFERROR(C14/C10," ") -> 0.43421651 | D15: =IFERROR(D14/D10," ") -> 0.44820154 | E15: =IFERROR(E14/E10," ") -> 0.45983729 | F15: =IFERROR(F14/F10," ") -> 0.43524611 | G15: =IFERROR(G14/G10," ") -> 0.44560181 | H15: =IFERROR(H14/H10," ") -> 0.42734674 | I15: =IFERROR(I14/I10," ") -> 0.42174166 | J15: =IFERROR(J14/J10," ") -> 0.42674166 | ... Q15: =IFERROR(Q14/Q10," ") -> 0.44174166
B17: Operating Expenses
B18: Demand Creation Expense | C18: 3592 | D18: 3114 | E18: 3850 | F18: 4060 | G18: 4285 | H18: 4689 | I18: =I$10*'Supporting Schedules'!I53 -> 3997.5749 | J18: =J$10*'Supporting Schedules'!J53 -> 4150.2752 | K18: =K$10*'Supporting Schedules'!K53 -> 4363.2769 | L18: =L$10*'Supporting Schedules'!L53 -> 4619.2217 | M18: =M$10*'Supporting Schedules'!M53 -> 4894.2744 | N18: =N$10*'Supporting Schedules'!N53 -> 5312.9249 | O18: =O$10*'Supporting Schedules'!O53 -> 5658.0964 | P18: =P$10*'Supporting Schedules'!P53 -> 6016.8746 | Q18: =Q$10*'Supporting Schedules'!Q53 -> 6388.9187
B19: Operating Overhead Expense | C19: =9534-C25 -> 8415 | D19: =9911-D25 -> 9114 | E19: =10954-E25 -> 10114 | F19: =12317-F25 -> 11614 | G19: =12291-G25 -> 11495 | H19: =11399-H25 -> 10624 | I19: =I$10*'Supporting Schedules'!I54 -> 11985.987 | J19: =J$10*'Supporting Schedules'!J54 -> 11471.734 | K19: =K$10*'Supporting Schedules'!K54 -> 12060.49 | L19: =L$10*'Supporting Schedules'!L54 -> 10604.075 | M19: =M$10*'Supporting Schedules'!M54 -> 11235.497 | N19: =N$10*'Supporting Schedules'!N54 -> 12196.568 | O19: =O$10*'Supporting Schedules'!O54 -> 12988.958 | P19: =P$10*'Supporting Schedules'!P54 -> 13812.584 | Q19: =Q$10*'Supporting Schedules'!Q54 -> 14666.664
B20: Other Operating Expense | C20: 139 | D20: 14 | E20: -181 | F20: -280 | G20: -228 | H20: -76 | I20: =I$10*'Supporting Schedules'!I55 -> -88.885179 | J20: =J$10*'Supporting Schedules'!J55 -> -92.280435 | K20: =K$10*'Supporting Schedules'!K55 -> -97.016479 | L20: =L$10*'Supporting Schedules'!L55 -> -102.70735 | M20: =M$10*'Supporting Schedules'!M55 -> -108.82309 | N20: =N$10*'Supporting Schedules'!N55 -> -118.13169 | O20: =O$10*'Supporting Schedules'!O55 -> -125.8065 | P20: =P$10*'Supporting Schedules'!P55 -> -133.78385 | Q20: =Q$10*'Supporting Schedules'!Q55 -> -142.05617
B21: Total Operating Expenses | C21: =SUM(C18:C20) -> 12146 | D21: =SUM(D18:D20) -> 12242 | E21: =SUM(E18:E20) -> 13783 | F21: =SUM(F18:F20) -> 15394 | G21: =SUM(G18:G20) -> 15552 | H21: =SUM(H18:H20) -> 15237 | I21: =SUM(I18:I20) -> 15894.677 | J21: =SUM(J18:J20) -> 15529.729 | ... Q21: =SUM(Q18:Q20) -> 20913.526
B23: EBITDA | C23: =C14-C21 -> 4095 | D23: =D14-D21 -> 7720 | E23: =E14-E21 -> 7696 | F23: =F14-F21 -> 6898 | G23: =G14-G21 -> 7335 | H23: =H14-H21 -> 4553 | I23: =I14-I21 -> 3849.7922 | J23: =J14-J21 -> 5211.9676 | ... Q23: =Q14-Q21 -> 12138.498
B25: Depreciation & Amortization | C25: =398+721 -> 1119 | D25: =744+53 -> 797 | E25: =717+123 -> 840 | F25: 703 | G25: 796 | H25: 775 | I25: ='Supporting Schedules'!I62 -> 838.12555 | J25: ='Supporting Schedules'!J62 -> 850.78682 | K25: ='Supporting Schedules'!K62 -> 858.53776 | L25: ='Supporting Schedules'!L62 -> 898.89707 | M25: ='Supporting Schedules'!M62 -> 911.85794 | N25: ='Supporting Schedules'!N62 -> 941.183 | O25: ='Supporting Schedules'!O62 -> 964.4807 | P25: ='Supporting Schedules'!P62 -> 997.78945 | Q25: ='Supporting Schedules'!Q62 -> 1042.1105
B27: EBIT | C27: =C23-C25 -> 2976 | D27: =D23-D25 -> 6923 | E27: =E23-E25 -> 6856 | F27: =F23-F25 -> 6195 | G27: =G23-G25 -> 6539 | H27: =H23-H25 -> 3778 | I27: =I23-I25 -> 3011.6666 | J27: =J23-J25 -> 4361.1808 | ... Q27: =Q23-Q25 -> 11096.387
B29: Non-Operating Expenses
B30: Interest Expense (Income), Net | C30: 89 | D30: 262 | E30: 205 | F30: -6 | G30: -161 | H30: -107 | I30: =I10*'Supporting Schedules'!I57 -> 55.310258 | J30: =J10*'Supporting Schedules'!J57 -> 57.423012 | K30: =K10*'Supporting Schedules'!K57 -> 60.370093 | L30: =L10*'Supporting Schedules'!L57 -> 63.911333 | M30: =M10*'Supporting Schedules'!M57 -> 67.71695 | N30: =N10*'Supporting Schedules'!N57 -> 73.509379 | O30: =O10*'Supporting Schedules'!O57 -> 78.285156 | P30: =P10*'Supporting Schedules'!P57 -> 83.249193 | Q30: =Q10*'Supporting Schedules'!Q57 -> 88.396778
B31: Total Non-Operating Expenses | C31: =SUM(C30:C30) -> 89 | D31: =SUM(D30:D30) -> 262 | E31: =SUM(E30:E30) -> 205 | F31: =SUM(F30:F30) -> -6 | G31: =SUM(G30:G30) -> -161 | H31: =SUM(H30:H30) -> -107 | I31: =SUM(I30:I30) -> 55.310258 | J31: =SUM(J30:J30) -> 57.423012 | ... Q31: =SUM(Q30:Q30) -> 88.396778
B33: EBT | C33: =C27-C31 -> 2887 | D33: =D27-D31 -> 6661 | E33: =E27-E31 -> 6651 | F33: =F27-F31 -> 6201 | G33: =G27-G31 -> 6700 | H33: =H27-H31 -> 3885 | I33: =I27-I31 -> 2956.3564 | J33: =J27-J31 -> 4303.7578 | ... Q33: =Q27-Q31 -> 11007.991
B35: Income Tax Expense | C35: 348 | D35: 934 | E35: 605 | F35: 1131 | G35: 1000 | H35: 666 | I35: =I33*'Supporting Schedules'!I69 -> 535.98741 | J35: =J33*'Supporting Schedules'!J69 -> 780.27129 | K35: =K33*'Supporting Schedules'!K69 -> 873.14923 | L35: =L33*'Supporting Schedules'!L69 -> 1367.5287 | M35: =M33*'Supporting Schedules'!M69 -> 1508.2716 | N35: =N33*'Supporting Schedules'!N69 -> 1646.112 | O35: =O33*'Supporting Schedules'!O69 -> 1759.9191 | P35: =P33*'Supporting Schedules'!P69 -> 1876.564 | Q35: =Q33*'Supporting Schedules'!Q69 -> 1995.7487
B37: Net Income (Loss) | C37: =C33-C35 -> 2539 | D37: =D33-D35 -> 5727 | E37: =E33-E35 -> 6046 | F37: =F33-F35 -> 5070 | G37: =G33-G35 -> 5700 | H37: =H33-H35 -> 3219 | I37: =I33-I35 -> 2420.369 | J37: =J33-J35 -> 3523.4865 | ... Q37: =Q33-Q35 -> 9012.2419
B38: Net Income % | C38: =IFERROR(C37/C10," ") -> 0.067882255 | D38: =IFERROR(D37/D10," ") -> 0.12858682 | E38: =IFERROR(E37/E10," ") -> 0.12943695 | F38: =IFERROR(F37/F10," ") -> 0.09899057 | G38: =IFERROR(G37/G10," ") -> 0.11097699 | H38: =IFERROR(H37/H10," ") -> 0.069511326 | I38: =IFERROR(I37/I10," ") -> 0.051699058 | J38: =IFERROR(J37/J10," ") -> 0.072492551 | ... Q38: =IFERROR(Q37/Q10," ") -> 0.12044898
B40: Balance Sheet
B42: Assets
B44: Current Assets
B45: Cash And Cash Equivalents | C45: 8348 | D45: 9889 | E45: 8574 | F45: 7441 | G45: 9860 | H45: 7464 | I45: =H45+I123 -> 7757.6 | J45: =I45+J123 -> 7127.3027 | K45: =J45+K123 -> 6566.8049 | L45: =K45+L123 -> 7410.9985 | M45: =L45+M123 -> 8462.0803 | N45: =M45+N123 -> 9355.7508 | O45: =N45+O123 -> 10435.864 | P45: =O45+P123 -> 11594.285 | Q45: =P45+Q123 -> 12838.554
B46: Short-Term Investments | C46: 439 | D46: 3587 | E46: 4423 | F46: 3234 | G46: 1722 | H46: 1687 | I46: ='Supporting Schedules'!I72*'Financial Statements'!I$10 -> 1561.0546 | J46: ='Supporting Schedules'!J72*'Financial Statements'!J$10 -> 1620.6841 | K46: ='Supporting Schedules'!K72*'Financial Statements'!K$10 -> 1703.8614 | L46: ='Supporting Schedules'!L72*'Financial Statements'!L$10 -> 1803.8079 | M46: ='Supporting Schedules'!M72*'Financial Statements'!M$10 -> 1911.2162 | N46: ='Supporting Schedules'!N72*'Financial Statements'!N$10 -> 2074.6993 | O46: ='Supporting Schedules'!O72*'Financial Statements'!O$10 -> 2209.489 | P46: ='Supporting Schedules'!P72*'Financial Statements'!P$10 -> 2349.592 | Q46: ='Supporting Schedules'!Q72*'Financial Statements'!Q$10 -> 2494.8753
B47: Accounts Recievable, Net | C47: 2749 | D47: 4463 | E47: 4667 | F47: 4131 | G47: 4427 | H47: 4717 | I47: ='Financial Statements'!I10/'Supporting Schedules'!I73 -> 4166.9201 | J47: ='Financial Statements'!J10/'Supporting Schedules'!J73 -> 4326.089 | K47: ='Financial Statements'!K10/'Supporting Schedules'!K73 -> 4548.1139 | L47: ='Financial Statements'!L10/'Supporting Schedules'!L73 -> 4814.901 | M47: ='Financial Statements'!M10/'Supporting Schedules'!M73 -> 5101.6056 | N47: ='Financial Statements'!N10/'Supporting Schedules'!N73 -> 5537.9909 | O47: ='Financial Statements'!O10/'Supporting Schedules'!O73 -> 5897.7846 | P47: ='Financial Statements'!P10/'Supporting Schedules'!P73 -> 6271.7613 | Q47: ='Financial Statements'!Q10/'Supporting Schedules'!Q73 -> 6659.5659
B48: Inventories | C48: 7367 | D48: 6854 | E48: 8420 | F48: 8454 | G48: 7519 | H48: 7489 | I48: ='Financial Statements'!I12/'Supporting Schedules'!I74 -> 8039.4745 | J48: ='Financial Statements'!J12/'Supporting Schedules'!J74 -> 8274.3983 | K48: ='Financial Statements'!K12/'Supporting Schedules'!K74 -> 8623.1856 | L48: ='Financial Statements'!L12/'Supporting Schedules'!L74 -> 9048.6873 | M48: ='Financial Statements'!M12/'Supporting Schedules'!M74 -> 9502.3863 | N48: ='Financial Statements'!N12/'Supporting Schedules'!N74 -> 10315.209 | O48: ='Financial Statements'!O12/'Supporting Schedules'!O74 -> 10985.371 | P48: ='Financial Statements'!P12/'Supporting Schedules'!P74 -> 11681.95 | Q48: ='Financial Statements'!Q12/'Supporting Schedules'!Q74 -> 12404.285
B49: Prepaid Expenses and Other Current Assets | C49: 1653 | D49: 1498 | E49: 2129 | F49: 1942 | G49: 1854 | H49: 2005 | I49: ='Supporting Schedules'!I75*'Financial Statements'!I$10 -> 1878.259 | J49: ='Supporting Schedules'!J75*'Financial Statements'!J$10 -> 1950.0052 | K49: ='Supporting Schedules'!K75*'Financial Statements'!K$10 -> 2050.0839 | L49: ='Supporting Schedules'!L75*'Financial Statements'!L$10 -> 2170.3395 | M49: ='Supporting Schedules'!M75*'Financial Statements'!M$10 -> 2299.5729 | N49: ='Supporting Schedules'!N75*'Financial Statements'!N$10 -> 2496.2757 | O49: ='Supporting Schedules'!O75*'Financial Statements'!O$10 -> 2658.4544 | P49: ='Supporting Schedules'!P75*'Financial Statements'!P$10 -> 2827.0261 | Q49: ='Supporting Schedules'!Q75*'Financial Statements'!Q$10 -> 3001.8309
B50: Total Current Assets | C50: =SUM(C45:C49) -> 20556 | D50: =SUM(D45:D49) -> 26291 | E50: =SUM(E45:E49) -> 28213 | F50: =SUM(F45:F49) -> 25202 | G50: =SUM(G45:G49) -> 25382 | H50: =SUM(H45:H49) -> 23362 | I50: =SUM(I45:I49) -> 23403.308 | J50: =SUM(J45:J49) -> 23298.479 | ... Q50: =SUM(Q45:Q49) -> 37399.111
B52: Non-Current Assets
B53: Property, Plant & Equipment, Net | C53: 4866 | D53: 4904 | E53: 4791 | F53: 5081 | G53: 5000 | H53: 4828 | I53: ='Supporting Schedules'!I63 -> 4599.2413 | J53: ='Supporting Schedules'!J63 -> 4598.0815 | K53: ='Supporting Schedules'!K63 -> 4632.7756 | L53: ='Supporting Schedules'!L63 -> 4544.2644 | M53: ='Supporting Schedules'!M63 -> 4491.0471 | N53: ='Supporting Schedules'!N63 -> 4481.9517 | O53: ='Supporting Schedules'!O63 -> 4510.1148 | P53: ='Supporting Schedules'!P63 -> 4567.9124 | Q53: ='Supporting Schedules'!Q63 -> 4646.6595
B54: Operating Lease Right-of-Use Assets, Net | C54: 3097 | D54: 3113 | E54: 2926 | F54: 2923 | G54: 2718 | H54: 2712 | I54: =I$10*'Supporting Schedules'!I84 -> 2995.4022 | J54: =J$10*'Supporting Schedules'!J84 -> 3109.8212 | K54: =K$10*'Supporting Schedules'!K84 -> 3269.4244 | L54: =L$10*'Supporting Schedules'!L84 -> 3461.2051 | M54: =M$10*'Supporting Schedules'!M84 -> 3667.3035 | N54: =N$10*'Supporting Schedules'!N84 -> 3981.0003 | O54: =O$10*'Supporting Schedules'!O84 -> 4239.639 | P54: =P$10*'Supporting Schedules'!P84 -> 4508.4732 | Q54: =Q$10*'Supporting Schedules'!Q84 -> 4787.2476
B55: Identifiable Intangible Assets, Net | C55: 274 | D55: 269 | E55: 286 | F55: 274 | G55: 259 | H55: 259 | I55: =I$10*'Supporting Schedules'!I85 -> 276.79146 | J55: =J$10*'Supporting Schedules'!J85 -> 287.36441 | K55: =K$10*'Supporting Schedules'!K85 -> 302.11261 | L55: =L$10*'Supporting Schedules'!L85 -> 319.83418 | M55: =M$10*'Supporting Schedules'!M85 -> 338.8788 | N55: =N$10*'Supporting Schedules'!N85 -> 367.86609 | O55: =O$10*'Supporting Schedules'!O85 -> 391.76571 | P55: =P$10*'Supporting Schedules'!P85 -> 416.60746 | Q55: =Q$10*'Supporting Schedules'!Q85 -> 442.36773
...

Sheet DCF Valuation
B1: Sauder Capital Markets Challenge
B2: =company -> Nike
B3: Financial Model
B4: DCF Valuation
B6: Input Assumptions
B8: Capital Structure
B9: Equity | C9: 95536.15
B10: % Equity | C10: =IFERROR(C9/C13,"") -> 0.89659718
B11: Debt | C11: 11018
B12: % Debt | C12: =IFERROR(C11/C13,"") -> 0.10340282
B13: Total Capitalization | C13: =SUM(C9,C11) -> 106554.15
B16: Weighted Average Cost of Capital (WACC)
B17: Expected Market Return | C17: 0.0891
B18: Risk Free Rate | C18: 0.0416
B19: Market Risk Premium | C19: =rm-rf -> 0.0475
B20: Beta | C20: 0.93
B21: Cost of Equity | C21: =rf+beta*mrp -> 0.085775
B22: Pre-Tax Cost of Debt | C22: 0.0415
B23: Effective Tax Rate | C23: 0.1813
B24: After Tax Cost Of Debt | C24: =costofdebt*(1-taxrate) -> 0.03397605
B25: WACC | C25: =IFERROR(C10*re+C12*rd,"") -> 0.080418842
B28: Unlevered Free Cash Flow Calculation
B30: Years | D30: 2020 | E30: =D30+1 -> 2021 | F30: =E30+1 -> 2022 | G30: =F30+1 -> 2023 | H30: =G30+1 -> 2024 | I30: =H30+1 -> 2025 | J30: =I30+1 -> 2026 | K30: =J30+1 -> 2027 | L30: =K30+1 -> 2028 | ... R30: =Q30+1 -> 2034
B32: EBIT | D32: ='Financial Statements'!C27 -> 2976 | E32: ='Financial Statements'!D27 -> 6923 | F32: ='Financial Statements'!E27 -> 6856 | G32: ='Financial Statements'!F27 -> 6195 | H32: ='Financial Statements'!G27 -> 6539 | I32: ='Financial Statements'!H27 -> 3778 | J32: ='Financial Statements'!I27 -> 3011.6666 | K32: ='Financial Statements'!J27 -> 4361.1808 | ... R32: ='Financial Statements'!Q27 -> 11096.387
B33: Times: (1 - Tax Rate) | D33: =1-'Supporting Schedules'!C69 -> 0.87945965 | E33: =1-'Supporting Schedules'!D69 -> 0.85978081 | F33: =1-'Supporting Schedules'!E69 -> 0.90903624 | G33: =1-'Supporting Schedules'!F69 -> 0.81761006 | H33: =1-'Supporting Schedules'!G69 -> 0.85074627 | I33: =1-'Supporting Schedules'!H69 -> 0.82857143 | J33: =1-'Supporting Schedules'!I69 -> 0.8187 | K33: =1-'Supporting Schedules'!J69 -> 0.8187 | ... R33: =1-'Supporting Schedules'!Q69 -> 0.8187
B34: Equals: NOPAT | D34: =D32*D33 -> 2617.2719 | E34: =E32*E33 -> 5952.2626 | F34: =F32*F33 -> 6232.3524 | G34: =G32*G33 -> 5065.0943 | H34: =H32*H33 -> 5563.0299 | I34: =I32*I33 -> 3130.3429 | J34: =J32*J33 -> 2465.6515 | K34: =K32*K33 -> 3570.4987 | ... R34: =R32*R33 -> 9084.6123
B35: Plus: Depreciation & Amortization | D35: ='Financial Statements'!C25 -> 1119 | E35: ='Financial Statements'!D25 -> 797 | F35: ='Financial Statements'!E25 -> 840 | G35: ='Financial Statements'!F25 -> 703 | H35: ='Financial Statements'!G25 -> 796 | I35: ='Financial Statements'!H25 -> 775 | J35: ='Financial Statements'!I25 -> 838.12555 | K35: ='Financial Statements'!J25 -> 850.78682 | ... R35: ='Financial Statements'!Q25 -> 1042.1105
B36: Less: Change In Working Capital | D36: ='Financial Statements'!C101 -> 0 | E36: ='Financial Statements'!D101 -> -2801 | F36: ='Financial Statements'!E101 -> -2681 | G36: ='Financial Statements'!F101 -> 904 | H36: ='Financial Statements'!G101 -> 2576 | I36: ='Financial Statements'!H101 -> 597 | J36: ='Financial Statements'!I101 -> 1064.6954 | K36: ='Financial Statements'!J101 -> -479.72633 | ... R36: ='Financial Statements'!Q101 -> -863.30902
B37: Less: Capital Expenditures | D37: =-'Supporting Schedules'!C61 -> -1086 | E37: =-'Supporting Schedules'!D61 -> -695 | F37: =-'Supporting Schedules'!E61 -> -758 | G37: =-'Supporting Schedules'!F61 -> -969 | H37: =-'Supporting Schedules'!G61 -> -812 | I37: =-'Supporting Schedules'!H61 -> -430 | J37: =-'Supporting Schedules'!I61 -> -818.36686 | K37: =-'Supporting Schedules'!J61 -> -849.62702 | ... R37: =-'Supporting Schedules'!Q61 -> -1120.8576
B38: Equals: Unlevered Free Cash Flow | D38: =SUM(D34:D37) -> 2650.2719 | E38: =SUM(E34:E37) -> 3253.2626 | F38: =SUM(F34:F37) -> 3633.3524 | G38: =SUM(G34:G37) -> 5703.0943 | H38: =SUM(H34:H37) -> 8123.0299 | I38: =SUM(I34:I37) -> 4072.3429 | J38: =SUM(J34:J37) -> 3550.1056 | K38: =SUM(K34:K37) -> 3091.9322 | ... R38: =SUM(R34:R37) -> 8142.5562
B39: Discount Period | J39: 1 | K39: =J39+1 -> 2 | L39: =K39+1 -> 3 | M39: =L39+1 -> 4 | N39: =M39+1 -> 5 | O39: =N39+1 -> 6 | P39: =O39+1 -> 7 | Q39: =P39+1 -> 8 | R39: =Q39+1 -> 9
B40: Equals: Present Value of Unlevered Free Cash Flow | D40: =D38/(1+wacc)^D39 -> 2650.2719 | E40: =E38/(1+wacc)^E39 -> 3253.2626 | F40: =F38/(1+wacc)^F39 -> 3633.3524 | G40: =G38/(1+wacc)^G39 -> 5703.0943 | H40: =H38/(1+wacc)^H39 -> 8123.0299 | I40: =I38/(1+wacc)^I39 -> 4072.3429 | J40: =J38/(1+wacc)^J39 -> 3285.8605 | K40: =K38/(1+wacc)^K39 -> 2648.7786 | ... R40: =R38/(1+wacc)^R39 -> 4059.1156
B43: Discounted Cash Flow Valuation
B45: Perpetuity Growth Method | G45: Sensitivity Table
B46: Perpetuity Growth Rate | D46: 0.02
B47: Present Value of Terminal Value | D47: =IFERROR(R38*(1+tgr)/(wacc-tgr)," ")*(1/(1+wacc)^9) -> 68526.601 | I47: Growth Rate
B48: Terminal Value as % of Enterprise Value | D48: =IFERROR(D47/D51,0) -> 0.67032452 | H48: =D57 -> 66.75348 | I48: =J48-0.25% -> 0.015 | J48: =K48-0.25% -> 0.0175 | K48: 0.02 | L48: =K48+0.25% -> 0.0225 | M48: =L48+0.25% -> 0.025
B49: Plus: Present Value of Forecast FCF | D49: =SUM(J40:R40) -> 33702.393 | G49: WACC | H49: =H50+0.25% -> 0.085418842 | I49: 57.813737 | J49: 59.308284 | K49: 60.91706 | L49: 62.653681 | M49: 64.534018
B50: Forecast Period as % of Enterprise Value | D50: =IFERROR(D49/D51,0) -> 0.32967548 | H50: =H51+0.25% -> 0.082918842 | I50: 60.309739 | J50: 61.948468 | K50: 63.717422 | L50: 65.632768 | M50: 67.713461
B51: Equals: Enterprise Value | D51: =SUM(D47,D49) -> 102228.99 | H51: 0.080418842 | I51: 63.000423 | J51: 64.80239 | K51: 66.75348 | L51: 68.873003 | M51: 71.183753 | P51: 11
...

Sheet Supporting Schedules
B1: Sauder Capital Markets Challenge
B2: =company -> Nike
B3: Financial Model
B4: Supporting Schedules
B6: Years | C6: 2020 | D6: =C6+1 -> 2021 | E6: =D6+1 -> 2022 | F6: =E6+1 -> 2023 | G6: =F6+1 -> 2024 | H6: =G6+1 -> 2025 | I6: =H6+1 -> 2026 | J6: =I6+1 -> 2027 | K6: =J6+1 -> 2028 | ... Q6: =P6+1 -> 2034
A8: d | B8: Revenue Build
B10: ='Financial Statements'!B10 -> Revenue | C10: =SUM(C12,C18:C19) -> 37403 | D10: =SUM(D12,D18:D19) -> 44538 | E10: =SUM(E12,E18:E19) -> 46710 | F10: =SUM(F12,F18:F19) -> 51217 | G10: =SUM(G12,G18:G19) -> 51362 | H10: =SUM(H12,H18:H19) -> 46309 | I10: =SUM(I12,I18:I19) -> 46816.501 | J10: =SUM(J12,J18:J19) -> 48604.808 | ... Q10: =SUM(Q12,Q18:Q19) -> 74822.066
B11: Segments:
B12: Nike | C12: =SUM(C13:C16) -> 35568 | D12: =SUM(D13:D16) -> 42293 | E12: =SUM(E13:E16) -> 44436 | F12: =SUM(F13:F16) -> 48763 | G12: =SUM(G13:G16) -> 49322 | H12: =SUM(H13:H16) -> 44714 | I12: =SUM(I13:I16) -> 45574.341 | J12: =SUM(J13:J16) -> 47345.123 | ... Q12: =SUM(Q13:Q16) -> 72771.674
B13: Footwear | C13: 23305 | D13: 28021 | E13: 29143 | F13: 33135 | G13: 33427 | H13: 29510 | I13: =H13*(1+I26) -> 30247.75 | J13: =I13*(1+J26) -> 31608.899 | K13: =J13*(1+K26) -> 33347.388 | L13: =K13*(1+L26) -> 35514.968 | M13: =L13*(1+M26) -> 37823.441 | N13: =M13*(1+N26) -> 41794.903 | O13: =N13*(1+O26) -> 44929.52 | P13: =O13*(1+P26) -> 48299.234 | Q13: =P13*(1+Q26) -> 51921.677 | R13: Edited to closer reflect consensus EBIT expectations
B14: Apparel | C14: 10953 | D14: 12865 | E14: 13567 | F14: 13843 | G14: 13775 | H14: 12965 | I14: =H14*(1+I27) -> 12835.35 | J14: =I14*(1+J27) -> 12963.703 | K14: =J14*(1+K27) -> 13352.615 | L14: =K14*(1+L27) -> 13753.193 | M14: =L14*(1+M27) -> 14165.789 | N14: =M14*(1+N27) -> 14590.762 | O14: =N14*(1+O27) -> 15028.485 | P14: =O14*(1+P27) -> 15479.34 | Q14: =P14*(1+Q27) -> 15943.72
B15: Equipment | C15: 1280 | D15: 1382 | E15: 1624 | F15: 1727 | G15: 2075 | H15: 2191 | I15: =H15*(1+I28) -> 2443.2405 | J15: =I15*(1+J28) -> 2724.5205 | K15: =J15*(1+K28) -> 3038.183 | L15: =K15*(1+L28) -> 3387.9561 | M15: =L15*(1+M28) -> 3777.9971 | N15: =M15*(1+N28) -> 4137.3819 | O15: =N15*(1+O28) -> 4448.2059 | P15: =O15*(1+P28) -> 4693.4166 | Q15: =P15*(1+Q28) -> 4858.2764
B16: Global Brand Divisions | C16: 30 | D16: 25 | E16: 102 | F16: 58 | G16: 45 | H16: 48 | I16: =H16*(1+I29) -> 48 | J16: =I16*(1+J29) -> 48 | K16: =J16*(1+K29) -> 48 | L16: =K16*(1+L29) -> 48 | M16: =L16*(1+M29) -> 48 | N16: =M16*(1+N29) -> 48 | O16: =N16*(1+O29) -> 48 | P16: =O16*(1+P29) -> 48 | Q16: =P16*(1+Q29) -> 48
B18: Converse | C18: 1846 | D18: 2205 | E18: 2346 | F18: 2427 | G18: 2082 | H18: 1692 | I18: =H18*(1+I31) -> 1319.76 | J18: =I18*(1+J31) -> 1323.3171 | K18: =J18*(1+K31) -> 1366.5833 | L18: =K18*(1+L31) -> 1438.5957 | M18: =L18*(1+M31) -> 1543.1748 | N18: =M18*(1+N31) -> 1686.2198 | O18: =N18*(1+O31) -> 1842.5244 | P18: =O18*(1+P31) -> 1976.4672 | Q18: =P18*(1+Q31) -> 2080.6176
B19: Corporate | C19: -11 | D19: 40 | E19: -72 | F19: 27 | G19: -42 | H19: -97 | I19: =H19*(1+I32) -> -77.6 | J19: =I19*(1+J32) -> -63.632 | K19: =J19*(1+K32) -> -53.45088 | L19: =K19*(1+L32) -> -45.967757 | M19: =L19*(1+M32) -> -40.451626 | N19: =M19*(1+N32) -> -36.406463 | O19: =N19*(1+O32) -> -33.493946 | P19: =O19*(1+P32) -> -31.48431 | Q19: =P19*(1+Q32) -> -30.224937
B21: Assumptions | H21: V
B23: Revenue Growth | D23: =D10/C10-1 -> 0.1907601 | E23: =E10/D10-1 -> 0.048767345 | F23: =F10/E10-1 -> 0.096488975 | G23: =G10/F10-1 -> 0.0028310912 | H23: =H10/G10-1 -> -0.098380125 | I23: =I10/H10-1 -> 0.010959005 | J23: =J10/I10-1 -> 0.038198226 | K23: =K10/J10-1 -> 0.051322296 | ... Q23: =Q10/P10-1 -> 0.06183345
B25: Nike Growth | D25: =D12/C12-1 -> 0.18907445 | E25: =E12/D12-1 -> 0.050670324 | F25: =F12/E12-1 -> 0.097376001 | G25: =G12/F12-1 -> 0.01146361 | H25: =H12/G12-1 -> -0.093426868 | I25: =I12/H12-1 -> 0.019240966 | J25: =J12/I12-1 -> 0.038854806 | K25: =K12/J12-1 -> 0.051558912 | ... Q25: =Q12/P12-1 -> 0.062050251
B26: Footwear Growth | D26: =D13/C13-1 -> 0.20236001 | E26: =E13/D13-1 -> 0.040041398 | F26: =F13/E13-1 -> 0.13697972 | G26: =G13/F13-1 -> 0.008812434 | H26: =H13/G13-1 -> -0.11718072 | I26: 0.025 | J26: =I26+0.02 -> 0.045 | K26: =J26+0.01 -> 0.055 | L26: =K26+0.01 -> 0.065 | M26: =L26 -> 0.065 | N26: =M26+0.04 -> 0.105 | O26: =N26-0.03 -> 0.075 | P26: =O26 -> 0.075 | Q26: =P26 -> 0.075
B27: Apparel Growth | D27: =D14/C14-1 -> 0.17456405 | E27: =E14/D14-1 -> 0.054566654 | F27: =F14/E14-1 -> 0.020343481 | G27: =G14/F14-1 -> -0.00491223 | H27: =H14/G14-1 -> -0.058802178 | I27: -0.01 | J27: =I27+0.02 -> 0.01 | K27: =J27+0.02 -> 0.03 | L27: =K27 -> 0.03 | M27: =L27 -> 0.03 | N27: =M27 -> 0.03 | O27: =N27 -> 0.03 | P27: =O27 -> 0.03 | Q27: =P27 -> 0.03
B28: Equipment Growth | D28: =D15/C15-1 -> 0.0796875 | E28: =E15/D15-1 -> 0.17510854 | F28: =F15/E15-1 -> 0.063423645 | G28: =G15/F15-1 -> 0.2015055 | H28: =H15/G15-1 -> 0.055903614 | I28: =AVERAGE(D28:H28) -> 0.11512576 | J28: =I28 -> 0.11512576 | K28: =J28 -> 0.11512576 | L28: =K28 -> 0.11512576 | M28: =L28 -> 0.11512576 | N28: =M28-0.02 -> 0.09512576 | O28: =N28-0.02 -> 0.07512576 | P28: =O28-0.02 -> 0.05512576 | Q28: =P28-0.02 -> 0.03512576
B29: Global Brand Divisions Growth | D29: =D16/C16-1 -> -0.16666667 | E29: =E16/D16-1 -> 3.08 | F29: =F16/E16-1 -> -0.43137255 | G29: =G16/F16-1 -> -0.22413793 | H29: =H16/G16-1 -> 0.066666667 | I29: 0 | J29: 0 | K29: 0 | L29: 0 | M29: 0 | N29: 0 | O29: 0 | P29: 0 | Q29: 0
B31: Converse Growth | D31: =D18/C18-1 -> 0.19447454 | E31: =E18/D18-1 -> 0.063945578 | F31: =F18/E18-1 -> 0.034526854 | G31: =G18/F18-1 -> -0.1421508 | H31: =H18/G18-1 -> -0.18731988 | I31: -0.22 | J31: =AVERAGE(D31:H31)+0.01 -> 0.0026952568 | K31: =J31+0.03 -> 0.032695257 | L31: =K31+0.02 -> 0.052695257 | M31: =L31+0.02 -> 0.072695257 | N31: =M31+0.02 -> 0.092695257 | O31: =N31 -> 0.092695257 | P31: =O31-0.02 -> 0.072695257 | Q31: =P31-0.02 -> 0.052695257
B32: Corporate Growth | D32: =D19/C19-1 -> -4.6363636 | E32: =E19/D19-1 -> -2.8 | F32: =F19/E19-1 -> -1.375 | G32: =G19/F19-1 -> -2.5555556 | H32: =H19/G19-1 -> 1.3095238 | I32: -0.2 | J32: =I32+0.02 -> -0.18 | K32: =J32+0.02 -> -0.16 | L32: =K32+0.02 -> -0.14 | M32: =L32+0.02 -> -0.12 | N32: =M32+0.02 -> -0.1 | O32: =N32+0.02 -> -0.08 | P32: =O32+0.02 -> -0.06 | Q32: =P32+0.02 -> -0.04
B34: Consensus | H34: V
B36: Revenue | C36: =SUM(C38:C40) -> 37403 | D36: =SUM(D38:D40) -> 44538 | E36: =SUM(E38:E40) -> 46710 | F36: =SUM(F38:F40) -> 51217 | G36: =SUM(G38:G40) -> 51362 | H36: =SUM(H38:H40) -> 46309 | I36: =SUM(I38:I40) -> 46708.255 | J36: =SUM(J38:J40) -> 48660.381 | ... Q36: =SUM(Q38:Q40) -> 75134.285
B38: Nike | C38: 35568 | D38: 42293 | E38: 44436 | F38: 48763 | G38: 49322 | H38: 44714 | I38: 45429.364 | J38: 47373.681 | K38: 49610.314 | L38: 52491.955 | M38: 55575.15 | N38: 60558.502 | O38: 64405.492 | P38: 68602.51 | Q38: 73156.133
B39: Converse | C39: 1846 | D39: 2205 | E39: 2346 | F39: 2427 | G39: 2082 | H39: 1692 | I39: 1319.3512 | J39: 1340.0664 | K39: 1383.7194 | L39: 1440.5069 | M39: 1517.3903 | N39: 1682.9143 | O39: 1844.2032 | P39: 1941.8031 | Q39: 2045.2902
B40: Corporate | C40: -11 | D40: 40 | E40: -72 | F40: 27 | G40: -42 | H40: -97 | I40: -40.460848 | J40: -53.365619 | K40: -59.366697 | L40: -77.457266 | M40: -78.325983 | N40: -79.220763 | O40: -63.284772 | P40: -65.183315 | Q40: -67.138814
B42: Check: Deviation From Consensus | H42: V
B44: Revenue | C44: =C10-C36 -> 0 | D44: =D10-D36 -> 0 | E44: =E10-E36 -> 0 | F44: =F10-F36 -> 0 | G44: =G10-G36 -> 0 | H44: =H10-H36 -> 0 | I44: =I10-I36 -> 108.24585 | J44: =J10-J36 -> -55.573578 | ... Q44: =Q10-Q36 -> -312.21823
B46: Nike | C46: =C12-C38 -> 0 | D46: =D12-D38 -> 0 | E46: =E12-E38 -> 0 | F46: =F12-F38 -> 0 | G46: =G12-G38 -> 0 | H46: =H12-H38 -> 0 | I46: =I12-I38 -> 144.97619 | J46: =J12-J38 -> -28.55791 | ... Q46: =Q12-Q38 -> -384.45954
B47: Converse | C47: =C18-C39 -> 0 | D47: =D18-D39 -> 0 | E47: =E18-E39 -> 0 | F47: =F18-F39 -> 0 | G47: =G18-G39 -> 0 | H47: =H18-H39 -> 0 | I47: =I18-I39 -> 0.40881156 | J47: =J18-J39 -> -16.749287 | ... Q47: =Q18-Q39 -> 35.327431
B48: Corporate | C48: =C19-C40 -> 0 | D48: =D19-D40 -> 0 | E48: =E19-E40 -> 0 | F48: =F19-F40 -> 0 | G48: =G19-G40 -> 0 | H48: =H19-H40 -> 0 | I48: =I19-I40 -> -37.139152 | J48: =J19-J40 -> -10.266381 | ... Q48: =Q19-Q40 -> 36.913877
B50: Costs
B51: ='Financial Statements'!B13 -> COGS Margin % | C51: ='Financial Statements'!C13 -> 0.56578349 | D51: ='Financial Statements'!D13 -> 0.55179846 | E51: ='Financial Statements'!E13 -> 0.54016271 | F51: ='Financial Statements'!F13 -> 0.56475389 | G51: ='Financial Statements'!G13 -> 0.55439819 | H51: ='Financial Statements'!H13 -> 0.57265326 | I51: =AVERAGE(C51:H51)+0.02 -> 0.57825834 | J51: =I51-0.005 -> 0.57325834 | K51: =J51-0.005 -> 0.56825834 | L51: =K51-0.005 -> 0.56325834 | M51: =L51-0.005 -> 0.55825834 | N51: =M51 -> 0.55825834 | O51: =N51 -> 0.55825834 | P51: =O51 -> 0.55825834 | Q51: =P51 -> 0.55825834
B53: Demand Creation Expense Margin % | C53: ='Financial Statements'!C18/'Financial Statements'!C$10 -> 0.096035077 | D53: ='Financial Statements'!D18/'Financial Statements'!D$10 -> 0.069917823 | E53: ='Financial Statements'!E18/'Financial Statements'!E$10 -> 0.082423464 | F53: ='Financial Statements'!F18/'Financial Statements'!F$10 -> 0.079270555 | G53: ='Financial Statements'!G18/'Financial Statements'!G$10 -> 0.083427437 | H53: ='Financial Statements'!H18/'Financial Statements'!H$10 -> 0.10125462 | I53: =AVERAGE(C53:H53) -> 0.085388162 | J53: =I53 -> 0.085388162 | K53: =J53 -> 0.085388162 | L53: =K53 -> 0.085388162 | M53: =L53 -> 0.085388162 | N53: =M53 -> 0.085388162 | O53: =N53 -> 0.085388162 | P53: =O53 -> 0.085388162 | Q53: =P53 -> 0.085388162
B54: Operating Overhead Expense Margin % | C54: ='Financial Statements'!C19/'Financial Statements'!C$10 -> 0.22498195 | D54: ='Financial Statements'!D19/'Financial Statements'!D$10 -> 0.20463424 | E54: ='Financial Statements'!E19/'Financial Statements'!E$10 -> 0.21652751 | F54: ='Financial Statements'!F19/'Financial Statements'!F$10 -> 0.22676065 | G54: ='Financial Statements'!G19/'Financial Statements'!G$10 -> 0.22380359 | H54: ='Financial Statements'!H19/'Financial Statements'!H$10 -> 0.22941545 | I54: =AVERAGE(C54:H54)+0.035 -> 0.25602057 | J54: =I54-0.02 -> 0.23602057 | K54: =J54 -> 0.23602057 | L54: =K54-0.04 -> 0.19602057 | M54: =L54 -> 0.19602057 | N54: =M54 -> 0.19602057 | O54: =N54 -> 0.19602057 | P54: =O54 -> 0.19602057 | Q54: =P54 -> 0.19602057
B55: Other Operating Expenses Margin % | C55: ='Financial Statements'!C20/'Financial Statements'!C10 -> 0.0037162794 | D55: ='Financial Statements'!D20/'Financial Statements'!D10 -> 0.00031433832 | E55: ='Financial Statements'!E20/'Financial Statements'!E10 -> -0.0038749732 | F55: ='Financial Statements'!F20/'Financial Statements'!F10 -> -0.0054669348 | G55: ='Financial Statements'!G20/'Financial Statements'!G10 -> -0.0044390795 | H55: ='Financial Statements'!H20/'Financial Statements'!H10 -> -0.0016411497 | I55: =AVERAGE(B55:H55) -> -0.0018985866 | J55: =I55 -> -0.0018985866 | K55: =J55 -> -0.0018985866 | L55: =K55 -> -0.0018985866 | M55: =L55 -> -0.0018985866 | N55: =M55 -> -0.0018985866 | O55: =N55 -> -0.0018985866 | P55: =O55 -> -0.0018985866 | Q55: =P55 -> -0.0018985866
B57: Interest Expense (Income), Net Margin % | C57: ='Financial Statements'!C30/'Financial Statements'!C10 -> 0.0023794883 | D57: ='Financial Statements'!D30/'Financial Statements'!D10 -> 0.0058826171 | E57: ='Financial Statements'!E30/'Financial Statements'!E10 -> 0.0043887818 | F57: ='Financial Statements'!F30/'Financial Statements'!F10 -> -0.0001171486 | G57: ='Financial Statements'!G30/'Financial Statements'!G10 -> -0.0031346131 | H57: ='Financial Statements'!H30/'Financial Statements'!H10 -> -0.002310566 | I57: =AVERAGE(C57:H57) -> 0.0011814266 | J57: =I57 -> 0.0011814266 | K57: =J57 -> 0.0011814266 | L57: =K57 -> 0.0011814266 | M57: =L57 -> 0.0011814266 | N57: =M57 -> 0.0011814266 | O57: =N57 -> 0.0011814266 | P57: =O57 -> 0.0011814266 | Q57: =P57 -> 0.0011814266
...

Sheet Comparables 
B1: Sauder Capital Markets Challenge
B2: =company -> Nike Inc
B3: Financial Model
B4: Comparable Companies Analysis
B6: Current Share Price (USD) | C6: =Precedents!C8 -> 60
B7: Diluted Shares Outstanding (m) | C7: 1478.2
B8: Equity Value | C8: =dilutedshares*C6 -> 88692
B9: Net Debt | C9: =ABS(('DCF Valuation'!D52+'DCF Valuation'!D53)) -> 3554
B10: Enterprise Value | C10: =SUM(C8:C9) -> 92246
B13: Comparable Companies: Peer Universe
B15: (All figures in USDm unless otherwise specified) | H15: EBITDA | K15: Net Income | N15: EV/EBITDA | Q15: P/E
B16: Company Name | C16: Year End | D16: Ticker | E16: Price (USD) | F16: Market Cap | G16: Enterprise Value | H16: 2024A | I16: LTM 2025 | J16: NTM 2026 | K16: 2024A | L16: LTM 2025 | M16: NTM 2026 | N16: 2024A | O16: LTM 2025 | P16: NTM 2026 | Q16: 2024A | R16: LTM 2025 | S16: NTM 2026
B17: Adidas | C17: 46022 | D17: ETR: ADS | E17: 193.31 | F17: =E17*178.5 -> 34505.835 | G17: =F17-1206+6359+446 -> 40104.835 | H17: 2170.5 | I17: 3362 | J17: 4964 | K17: 895 | L17: 1435 | M17: =178.5*11.51 -> 2054.535 | N17: =IFERROR($G17/H17,"") -> 18.477233 | O17: =IFERROR($G17/I17,"") -> 11.928862 | P17: =IFERROR($G17/J17,"") -> 8.0791368 | Q17: =IFERROR($F17/K17,"") -> 38.554006 | R17: =IFERROR($F17/L17,"") -> 24.045878 | S17: =IFERROR($F17/M17,"") -> 16.794961
B18: On | C18: 46022 | D18: NYSE: ONON | E18: 48.57 | F18: =E18*326.5 -> 15858.105 | G18: =F18-1101+626 -> 15383.105 | H18: 274.6 | I18: 690.8 | J18: 865.7 | K18: 267.4 | L18: 296.37 | M18: 541.37 | N18: =IFERROR($G18/H18,"") -> 56.020047 | O18: =IFERROR($G18/I18,"") -> 22.268536 | P18: =IFERROR($G18/J18,"") -> 17.769556 | Q18: =IFERROR($F18/K18,"") -> 59.304806 | R18: =IFERROR($F18/L18,"") -> 53.507794 | S18: =IFERROR($F18/M18,"") -> 29.292545
B19: Deckers Outdoor Corporation | C19: 45747 | D19: NYSE: DECK | E19: 99.47 | F19: =E19*145.7 -> 14492.779 | G19: =F19-1415+350.7 -> 13428.479 | H19: 994.3 | I19: 1312 | J19: 1215 | K19: 759.6 | L19: 1016 | M19: =6.37*145.7 -> 928.109 | N19: =IFERROR($G19/H19,"") -> 13.50546 | O19: =IFERROR($G19/I19,"") -> 10.235121 | P19: =IFERROR($G19/J19,"") -> 11.052246 | Q19: =IFERROR($F19/K19,"") -> 19.079488 | R19: =IFERROR($F19/L19,"") -> 14.264546 | S19: =IFERROR($F19/M19,"") -> 15.615385
B20: Asics | C20: 46022 | D20: TSE: 7936 | E20: 24.3 | F20: =E20*716.7 -> 17415.81 | G20: =F20-791.25+701.66+10 -> 17336.22 | H20: 770.26 | I20: 1041 | J20: 1192 | K20: 405 | L20: 587 | M20: 682 | N20: =IFERROR($G20/H20,"") -> 22.506972 | O20: =IFERROR($G20/I20,"") -> 16.653429 | P20: =IFERROR($G20/J20,"") -> 14.543809 | Q20: =IFERROR($F20/K20,"") -> 43.002 | R20: =IFERROR($F20/L20,"") -> 29.669182 | S20: =IFERROR($F20/M20,"") -> 25.536378
B21: Under Armour | C21: 45747 | D21: NYSE: UAA | E21: 4.3 | F21: =E21*424 -> 1823.2 | G21: =F21-396+1900 -> 3327.2 | H21: 379 | I21: 338 | J21: 218 | K21: 0 | L21: 0 | M21: 0 | N21: =IFERROR($G21/H21,"") -> 8.7788918 | O21: =IFERROR($G21/I21,"") -> 9.843787 | P21: =IFERROR($G21/J21,"") -> 15.262385 | Q21: N/A | R21: N/A | S21: N/A
B22: Puma | C22: 46022 | D22: ETR: PUM | E22: 26.2 | F22: =145*E22 -> 3799 | G22: =F22-310+3178 -> 6667 | H22: 902 | I22: 330 | J22: 508 | K22: 0 | L22: 0 | M22: 0 | N22: =IFERROR($G22/H22,"") -> 7.3913525 | O22: =IFERROR($G22/I22,"") -> 20.20303 | P22: =IFERROR($G22/J22,"") -> 13.124016 | Q22: N/A | R22: N/A | S22: N/A
B24: Minimum | N24: =IFERROR(MIN(N$17:N22),"") -> 7.3913525 | O24: =IFERROR(MIN(O$17:O22),"") -> 9.843787 | P24: =IFERROR(MIN(P$17:P22),"") -> 8.0791368 | Q24: =IFERROR(MIN(Q$17:Q20),"") -> 19.079488 | R24: =IFERROR(MIN(R$17:R20),"") -> 14.264546 | S24: =IFERROR(MIN(S$17:S20),"") -> 15.615385
B25: Median | N25: =IFERROR(MEDIAN(N17:N22),"") -> 15.991347 | O25: =IFERROR(MEDIAN(O17:O22),"") -> 14.291146 | P25: =IFERROR(MEDIAN(P17:P22),"") -> 13.833912 | Q25: =IFERROR(MEDIAN(Q17:Q20),"") -> 40.778003 | R25: =IFERROR(MEDIAN(R17:R20),"") -> 26.85753 | S25: =IFERROR(MEDIAN(S17:S20),"") -> 21.16567
B26: Mean | N26: =IFERROR(AVERAGE(N17:N22),"") -> 21.113326 | O26: =IFERROR(AVERAGE(O17:O22),"") -> 15.188794 | P26: =IFERROR(AVERAGE(P17:P22),"") -> 13.305192 | Q26: =IFERROR(AVERAGE(Q17:Q20),"") -> 39.985075 | R26: =IFERROR(AVERAGE(R17:R20),"") -> 30.37185 | S26: =IFERROR(AVERAGE(S17:S20),"") -> 21.809817
B27: Maximum | N27: =IFERROR(MAX(N17:N22),"") -> 56.020047 | O27: =IFERROR(MAX(O17:O22),"") -> 22.268536 | P27: =IFERROR(MAX(P17:P22),"") -> 17.769556 | Q27: =IFERROR(MAX(Q17:Q20),"") -> 59.304806 | R27: =IFERROR(MAX(R17:R20),"") -> 53.507794 | S27: =IFERROR(MAX(S17:S20),"") -> 29.292545
B29: =company -> Nike Inc | C29: 45808 | D29: =[1]Cover!C3 -> NYSE: NKE | E29: =currentprice -> 58.71 | F29: =E29*dilutedshares -> 86785.122 | G29: =ev -> 92246 | H29: 7550 | I29: 3824 | J29: 4205 | K29: 5700 | L29: 2524 | M29: =1.92*dilutedshares -> 2838.144 | N29: =IFERROR($G29/H29,"") -> 12.218013 | O29: =IFERROR($G29/I29,"") -> 24.122908 | P29: =IFERROR($G29/J29,"") -> 21.937218 | Q29: =IFERROR($F29/K29,"") -> 15.22546 | R29: =IFERROR($F29/L29,"") -> 34.383963 | S29: =IFERROR($F29/M29,"") -> 30.578125
B32: Comparable Companies Valuation
D34: Multiple | G34: Implied Equity Value | J34: Implied Share Price (USD) | M34: Implied Return (%)
B35: Metric | D35: Lower Limit | E35: Median | F35: Upper Limit | G35: Lower Limit | H35: Median | I35: Upper Limit | J35: Lower Limit | K35: Median | L35: Upper Limit | M35: Lower Limit | N35: Median | O35: Upper Limit
B36: EV/EBITDA 2024A | D36: =$N$24 -> 7.3913525 | E36: =$N$25 -> 15.991347 | F36: =$N$27 -> 56.020047 | G36: =($H$29*D36)-netdebt -> 52250.712 | H36: =IFERROR(($H$29*E36)-netdebt,"") -> 117180.67 | I36: =($H$29*F36)-netdebt -> 419397.36 | J36: =IFERROR(G36/dilutedshares,"") -> 35.347525 | K36: =IFERROR(H36/dilutedshares,"") -> 79.272539 | L36: =IFERROR(I36/dilutedshares,"") -> 283.72166 | M36: =IFERROR((J36/currentprice)-1,"") -> -0.39793008 | N36: =IFERROR((K36/currentprice)-1,"") -> 0.35023913 | O36: =IFERROR((L36/currentprice)-1,"") -> 3.8325951
B37: EV/EBITDA 2025E | D37: =$O$24 -> 9.843787 | E37: =$O$25 -> 14.291146 | F37: =$O$27 -> 22.268536 | G37: =($I$29*D37)-netdebt -> 34088.641 | H37: =($I$29*E37)-netdebt -> 51095.342 | I37: =($I$29*F37)-netdebt -> 81600.883 | J37: =IFERROR(G37/dilutedshares,"") -> 23.060913 | K37: =IFERROR(H37/dilutedshares,"") -> 34.565919 | L37: =IFERROR(I37/dilutedshares,"") -> 55.202871 | M37: =IFERROR((J37/currentprice)-1,"") -> -0.60720639 | N37: =IFERROR((K37/currentprice)-1,"") -> -0.41124307 | O37: =IFERROR((L37/currentprice)-1,"") -> -0.059736489
B38: EV/EBITDA 2026E | D38: =$P$24 -> 8.0791368 | E38: =$P$25 -> 13.833912 | F38: =$P$27 -> 17.769556 | G38: =($J$29*D38)-netdebt -> 30418.77 | H38: =($J$29*E38)-netdebt -> 54617.601 | I38: =($J$29*F38)-netdebt -> 71166.985 | J38: =IFERROR(G38/dilutedshares,"") -> 20.578251 | K38: =IFERROR(H38/dilutedshares,"") -> 36.948722 | L38: =IFERROR(I38/dilutedshares,"") -> 48.144354 | M38: =IFERROR((J38/currentprice)-1,"") -> -0.64949326 | N38: =IFERROR((K38/currentprice)-1,"") -> -0.37065709 | O38: =IFERROR((L38/currentprice)-1,"") -> -0.1799633
D40: Multiple | G40: Implied Equity Value | J40: Implied Share Price (USD) | M40: Implied Return (%)
B41: Metric | D41: Lower Limit | E41: Median | F41: Upper Limit | G41: Lower Limit | H41: Median | I41: Upper Limit | J41: Lower Limit | K41: Median | L41: Upper Limit | M41: Lower Limit | N41: Median | O41: Upper Limit
B42: P/E 2024A | D42: =IFERROR(MIN($Q$17:$Q$20),"") -> 19.079488 | E42: =IFERROR(MEDIAN($Q$17:$Q$20),"") -> 40.778003 | F42: =IFERROR(MAX($Q$17:$Q$20),"") -> 59.304806 | G42: =IFERROR(($K$29*D42),"") -> 108753.08 | H42: =IFERROR(($K$29*E42),"") -> 232434.62 | I42: =IFERROR(($K$29*F42),"") -> 338037.39 | J42: =IFERROR(G42/dilutedshares,"") -> 73.57129 | K42: =IFERROR(H42/dilutedshares,"") -> 157.24166 | L42: =IFERROR(I42/dilutedshares,"") -> 228.68177 | M42: =IFERROR((J42/currentprice)-1,"") -> 0.25313047 | N42: =IFERROR((K42/currentprice)-1,"") -> 1.6782772 | O42: =IFERROR((L42/currentprice)-1,"") -> 2.8951076
B43: P/E 2025E | D43: =IFERROR(MIN($R$17:$R$20),"") -> 14.264546 | E43: =IFERROR(MEDIAN($R$17:$R$20),"") -> 26.85753 | F43: =IFERROR(MAX($R$17:$R$20),"") -> 53.507794 | G43: =IFERROR(($L$29*D43),"") -> 36003.715 | H43: =IFERROR(($L$29*E43),"") -> 67788.406 | I43: =IFERROR(($L$29*F43),"") -> 135053.67 | J43: =IFERROR(G43/dilutedshares,"") -> 24.356457 | K43: =IFERROR(H43/dilutedshares,"") -> 45.858751 | L43: =IFERROR(I43/dilutedshares,"") -> 91.3636 | M43: =IFERROR((J43/currentprice)-1,"") -> -0.58513955 | N43: =IFERROR((K43/currentprice)-1,"") -> -0.21889369 | O43: =IFERROR((L43/currentprice)-1,"") -> 0.55618463
B44: P/E 2026E | D44: =IFERROR(MIN($S$17:$S$20),"") -> 15.615385 | E44: =IFERROR(MEDIAN($S$17:$S$20),"") -> 21.16567 | F44: =IFERROR(MAX($S$17:$S$20),"") -> 29.292545 | G44: =IFERROR(($M$29*D44),"") -> 44318.71 | H44: =IFERROR(($M$29*E44),"") -> 60071.218 | I44: =IFERROR(($M$29*F44),"") -> 83136.46 | J44: =IFERROR(G44/dilutedshares,"") -> 29.981538 | K44: =IFERROR(H44/dilutedshares,"") -> 40.638086 | L44: =IFERROR(I44/dilutedshares,"") -> 56.241686 | M44: =IFERROR((J44/currentprice)-1,"") -> -0.48932825 | N44: =IFERROR((K44/currentprice)-1,"") -> -0.30781663 | O44: =IFERROR((L44/currentprice)-1,"") -> -0.042042478
D46: Multiple | G46: Implied Equity Value | J46: Implied Share Price (USD) | M46: Implied Return (%)
B47: Metric | D47: 25th Percentile | E47: Median | F47: 75th Percentile | G47: 25th Percentile | H47: Median | I47: 75th Percentile | J47: 25th Percentile | K47: Median | L47: 75th Percentile | M47: 25th Percentile | N47: Median | O47: 75th Percentile
B48: EV/EBITDA 2024A | D48: =_xlfn.PERCENTILE.EXC(N17:N22,0.25) -> 8.432007 | E48: =$N$25 -> 15.991347 | F48: =_xlfn.PERCENTILE.EXC(O17:O22,0.75) -> 20.719407 | G48: =($H$29*D48)-netdebt -> 60107.653 | H48: =IFERROR(($H$29*E48)-netdebt,"") -> 117180.67 | I48: =($H$29*F48)-netdebt -> 152877.52 | J48: =IFERROR(G48/dilutedshares,"") -> 40.662734 | K48: =IFERROR(H48/dilutedshares,"") -> 79.272539 | L48: =IFERROR(I48/dilutedshares,"") -> 103.42141 | M48: =IFERROR((J48/currentprice)-1,"") -> -0.3073968 | N48: =IFERROR((K48/currentprice)-1,"") -> 0.35023913 | O48: =IFERROR((L48/currentprice)-1,"") -> 0.76156371
B49: EV/EBITDA 2025E | D49: =_xlfn.PERCENTILE.EXC(O17:O22,0.25) -> 10.137288 | E49: =$O$25 -> 14.291146 | F49: =_xlfn.PERCENTILE.EXC(N17:N22,0.75) -> 30.885241 | G49: =($I$29*D49)-netdebt -> 35210.988 | H49: =($I$29*E49)-netdebt -> 51095.342 | I49: =($I$29*F49)-netdebt -> 114551.16 | J49: =IFERROR(G49/dilutedshares,"") -> 23.820179 | K49: =IFERROR(H49/dilutedshares,"") -> 34.565919 | L49: =IFERROR(I49/dilutedshares,"") -> 77.493682 | M49: =IFERROR((J49/currentprice)-1,"") -> -0.59427391 | N49: =IFERROR((K49/currentprice)-1,"") -> -0.41124307 | O49: =IFERROR((L49/currentprice)-1,"") -> 0.31994007
B50: EV/EBITDA 2026E | D50: =_xlfn.PERCENTILE.EXC(P17:P22,0.25) -> 10.308969 | E50: =$P$25 -> 13.833912 | F50: =_xlfn.PERCENTILE.EXC(P17:P22,0.75) -> 15.889178 | G50: =($J$29*D50)-netdebt -> 39795.214 | H50: =($J$29*E50)-netdebt -> 54617.601 | I50: =($J$29*F50)-netdebt -> 63259.994 | J50: =IFERROR(G50/dilutedshares,"") -> 26.9214 | K50: =IFERROR(H50/dilutedshares,"") -> 36.948722 | L50: =IFERROR(I50/dilutedshares,"") -> 42.795287 | M50: =IFERROR((J50/currentprice)-1,"") -> -0.5414512 | N50: =IFERROR((K50/currentprice)-1,"") -> -0.37065709 | O50: =IFERROR((L50/currentprice)-1,"") -> -0.27107328
D52: Multiple | G52: Implied Equity Value | J52: Implied Share Price (USD) | M52: Implied Return (%)
...

Sheet Precedents
B1: Sauder Capital Markets Challenge
B2: =company -> Nike
B3: Financial Model
B4: Precedent Transaction Analysis
B6: Financial Data
B8: Current Share Price (USD) | C8: =currentprice -> 60
B9: Diluted Shares Outstanding (m) | C9: ='Comparables '!dilutedshares -> 1478.2
B10: Net Debt | C10: ='Comparables '!netdebt -> 3554
B12: LTM Revenue | C12: 46309
B13: LTM EBITDA | C13: 4477
B14: LTM Net Income | C14: 3219
B15: LTM EPS | C15: 2.16
B18: Precedents Transactions
B20: (All figures in USDm unless otherwise specified) | F20: LTM Multiples
B21: Acquirer | C21: Target | D21: Announcement Date | E21: Transaction Value | F21: TV / Revenue | G21: TV / EBITDA | H21: Offer Price / EPS | I21: Rationale
B22: 3G Capital | C22: Skechers | D22: 45778 | E22: 9420 | F22: =E22/8969 -> 1.0502843 | G22: =E22/1200 -> 7.85 | H22: =63/4.16 -> 15.144231 | I22: Closest "pure footwear" precedent to Nike (global brand, scale, wholesale + DTC mxi)
B23: Dick's Sporting Goods | C23: Foot Locker | D23: 45778 | E23: 2500 | F23: =E23/7971 -> 0.31363693 | G23: 6.1 | H23: =24/1.37 -> 17.518248 | I23: This is a big channel control/ sneaker retail precedent
B24: Crocs | C24: HEYDUDE | D24: 44531 | E24: 2500 | F24: =E24/570 -> 4.3859649 | G24: 15 | H24: NA: non public | I24: Footwear brand add on, useful for thinking about what market pays for brand expansion
B25: Anta Sports | C25: Amer Sports | D25: 43441 | E25: 4600 | F25: =E25/2685 -> 1.7132216 | G25: =E25/284 -> 16.197183 | H25: =40/1.18 -> 33.898305 | I25: Shows what buyers pay for a portfolio of sports/ outdoor brands + Asia growth optionality
B26: JD Sports | C26: Finish Line | D26: 43160 | E26: 558 | F26: =E26/1839 -> 0.30342577 | G26: =E26/98 -> 5.6938776 | H26: =13.5/0.36 -> 37.5 | I26: Another sneaker-retail consolidation precedent
B30: Minimum | F30: =IFERROR(MIN(F$22:F28),"") -> 0.30342577 | G30: =IFERROR(MIN(G$22:G28),"") -> 5.6938776 | H30: =IFERROR(MIN(H$22:H28),"") -> 15.144231
B31: 25th Percentile | F31: =_xlfn.PERCENTILE.EXC(F22:F26,0.25) -> 0.30853135 | G31: =_xlfn.PERCENTILE.EXC(G22:G26,0.25) -> 5.8969388 | H31: =_xlfn.PERCENTILE.EXC(H22:H26,0.25) -> 15.737735
B32: Median | F32: =IFERROR(MEDIAN(F22:F28),"") -> 1.0502843 | G32: =IFERROR(MEDIAN(G22:G28),"") -> 7.85 | H32: =IFERROR(MEDIAN(H22:H28),"") -> 25.708277
B33: Mean | F33: =IFERROR(AVERAGE(F22:F28),"") -> 1.5533067 | G33: =IFERROR(AVERAGE(G22:G28),"") -> 10.168212 | H33: =IFERROR(AVERAGE(H22:H28),"") -> 26.015196
B34: 75th Percentile | F34: =_xlfn.PERCENTILE.EXC(F22:F26,0.75) -> 3.0495933 | G34: =_xlfn.PERCENTILE.EXC(G22:G26,0.75) -> 15.598592 | H34: =_xlfn.PERCENTILE.EXC(H22:H26,0.75) -> 36.599576
B35: Maximum | F35: =IFERROR(MAX(F22:F28),"") -> 4.3859649 | G35: =IFERROR(MAX(G22:G28),"") -> 16.197183 | H35: =IFERROR(MAX(H22:H28),"") -> 37.5
B38: Valuation
D40: TV / Revenue | G40: Offer Price / EPS
C41: Transaction Value | D41: Implied Equity Value | E41: Implied Share Price | G41: Implied Share Price
B42: Minimum | C42: =F30*$C$12 -> 14051.344 | D42: =C42-$C$10 -> 10497.344 | E42: =D42/$C$9 -> 7.101437 | G42: =H30*$C$15 -> 32.711538
B43: 25th Percentile | C43: =F31*$C$12 -> 14287.778 | D43: =C43-$C$10 -> 10733.778 | E43: =D43/$C$9 -> 7.2613844 | G43: =H31*$C$15 -> 33.993508
B44: Median | C44: =F32*$C$12 -> 48637.616 | D44: =C44-$C$10 -> 45083.616 | E44: =D44/$C$9 -> 30.498996 | G44: =H32*$C$15 -> 55.529878
B45: Mean | C45: =F33*$C$12 -> 71932.08 | D45: =C45-$C$10 -> 68378.08 | E45: =D45/$C$9 -> 46.257665 | G45: =H33*$C$15 -> 56.192823
B46: 75th Percentile | C46: =F34*$C$12 -> 141223.61 | D46: =C46-$C$10 -> 137669.61 | E46: =D46/$C$9 -> 93.13328 | G46: =H34*$C$15 -> 79.055085
B47: Maximum | C47: =F35*$C$12 -> 203109.65 | D47: =C47-$C$10 -> 199555.65 | E47: =D47/$C$9 -> 134.99909 | G47: =H35*$C$15 -> 81
C51: LTM Multiples
C52: TV / Revenue | D52: TV / EBITDA | E52: Offer Price / EPS
B53: Transaction Value | C53: =F34*C12 -> 141223.61 | D53: =G34*C13 -> 69834.894 | E53: =H34*C15 -> 79.055085
B54: Less: Net Debt | C54: =-C10 -> -3554 | D54: -3554
B55: Equals: Implied Value | C55: =SUM(C53:C54) -> 137669.61 | D55: =SUM(D53:D54) -> 66280.894 | E55: =SUM(E53:E54) -> 79.055085
...
